Traceback (most recent call last):
  File "/opt/hostedtoolcache/Python/3.10.17/x64/lib/python3.10/site-packages/jupyter_cache/executors/utils.py", line 58, in single_nb_execution
    executenb(
  File "/opt/hostedtoolcache/Python/3.10.17/x64/lib/python3.10/site-packages/nbclient/client.py", line 1319, in execute
    return NotebookClient(nb=nb, resources=resources, km=km, **kwargs).execute()
  File "/opt/hostedtoolcache/Python/3.10.17/x64/lib/python3.10/site-packages/jupyter_core/utils/__init__.py", line 165, in wrapped
    return loop.run_until_complete(inner)
  File "/opt/hostedtoolcache/Python/3.10.17/x64/lib/python3.10/asyncio/base_events.py", line 649, in run_until_complete
    return future.result()
  File "/opt/hostedtoolcache/Python/3.10.17/x64/lib/python3.10/site-packages/nbclient/client.py", line 709, in async_execute
    await self.async_execute_cell(
  File "/opt/hostedtoolcache/Python/3.10.17/x64/lib/python3.10/site-packages/nbclient/client.py", line 1062, in async_execute_cell
    await self._check_raise_for_error(cell, cell_index, exec_reply)
  File "/opt/hostedtoolcache/Python/3.10.17/x64/lib/python3.10/site-packages/nbclient/client.py", line 918, in _check_raise_for_error
    raise CellExecutionError.from_cell_and_msg(cell, exec_reply_content)
nbclient.exceptions.CellExecutionError: An error occurred while executing the following cell:
------------------
# Reverse the above calculation showing the energy ratio of T0 / T2,
# letting T1 supply wind speed and direction
er_out = erp.compute_energy_ratio(
    a_inest_turbines=[0], ref_turbines=[2], ws_turbines=[1], wd_turbines=[1], N=50
)
er_out.plot_energy_ratios()
------------------


[0;31m---------------------------------------------------------------------------[0m
[0;31mTypeError[0m                                 Traceback (most recent call last)
Cell [0;32mIn[8], line 3[0m
[1;32m      1[0m [38;5;66;03m# Reverse the above calculation showing the energy ratio of T0 / T2,[39;00m
[1;32m      2[0m [38;5;66;03m# letting T1 supply wind speed and direction[39;00m
[0;32m----> 3[0m er_out [38;5;241m=[39m [43merp[49m[38;5;241;43m.[39;49m[43mcompute_energy_ratio[49m[43m([49m
[1;32m      4[0m [43m    [49m[43ma_inest_turbines[49m[38;5;241;43m=[39;49m[43m[[49m[38;5;241;43m0[39;49m[43m][49m[43m,[49m[43m [49m[43mref_turbines[49m[38;5;241;43m=[39;49m[43m[[49m[38;5;241;43m2[39;49m[43m][49m[43m,[49m[43m [49m[43mws_turbines[49m[38;5;241;43m=[39;49m[43m[[49m[38;5;241;43m1[39;49m[43m][49m[43m,[49m[43m [49m[43mwd_turbines[49m[38;5;241;43m=[39;49m[43m[[49m[38;5;241;43m1[39;49m[43m][49m[43m,[49m[43m [49m[43mN[49m[38;5;241;43m=[39;49m[38;5;241;43m50[39;49m
[1;32m      5[0m [43m)[49m
[1;32m      6[0m er_out[38;5;241m.[39mplot_energy_ratios()

[0;31mTypeError[0m: compute_energy_ratio() got an unexpected keyword argument 'a_inest_turbines'

